<?xml version="1.0" encoding="utf-8"?>
<!-- This URDF was automatically created by SolidWorks to URDF Exporter! Originally created by Stephen Brawner (brawner@gmail.com) 
     Commit Version: 1.6.0-1-g15f4949  Build Version: 1.6.7594.29634
     For more information, please see http://wiki.ros.org/sw_urdf_exporter -->
<robot
  name="my_ros2_robot">
  <link
    name="base_link">
    <inertial>
      <origin
        xyz="0 0 0"
        rpy="0 0 0" />
      <mass
        value="1.1732" />
      <inertia
        ixx="0.0089048"
        ixy="-3.7577E-17"
        ixz="-1.2308E-16"
        iyy="0.013333"
        iyz="-0.00079096"
        izz="0.020676" />
    </inertial>
    <visual>
      <origin
        xyz="0 0 0"
        rpy="0 0 0" />
      <geometry>
        <mesh
          filename="package://my_ros2_robot/meshes/chassis.STL" />
      </geometry>
      <material
        name="">
        <color
          rgba="0.79216 0.81961 0.93333 1" />
      </material>
    </visual>
    <collision>
      <origin
        xyz="0 0 0"
        rpy="0 0 0" />
      <geometry>
        <mesh
          filename="package://my_ros2_robot/meshes/chassis.STL" />
      </geometry>
    </collision>
  </link>
  <link
    name="axle">
    <inertial>
      <origin
        xyz="6.9389E-18 0.044546 -2.7756E-17"
        rpy="0 0 0" />
      <mass
        value="0.36717" />
      <inertia
        ixx="0.0086477"
        ixy="-1.0791E-18"
        ixz="0"
        iyy="0.00039419"
        iyz="1.7487E-18"
        izz="0.0086477" />
    </inertial>
    <visual>
      <origin
        xyz="0 0 0"
        rpy="0 0 0" />
      <geometry>
        <mesh
          filename="package://my_ros2_robot/meshes/axle.STL" />
      </geometry>
      <material
        name="">
        <color
          rgba="0.79216 0.81961 0.93333 1" />
      </material>
    </visual>
    <collision>
      <origin
        xyz="0 0 0"
        rpy="0 0 0" />
      <geometry>
        <mesh
          filename="package://my_ros2_robot/meshes/axle.STL" />
      </geometry>
    </collision>
  </link>
  <joint
    name="axle_joint"
    type="continuous">
    <origin
      xyz="0 0 0"
      rpy="0 0 0" />
    <parent
      link="base_link" />
    <child
      link="axle" />
    <axis
      xyz="0 1 0" />
  </joint>
  <link
    name="steer">
    <inertial>
      <origin
        xyz="0 0 0"
        rpy="0 0 0" />
      <mass
        value="0" />
      <inertia
        ixx="0"
        ixy="0"
        ixz="0"
        iyy="0"
        iyz="0"
        izz="0" />
    </inertial>
    <visual>
      <origin
        xyz="0 0 0"
        rpy="0 0 0" />
      <geometry>
        <mesh
          filename="package://my_ros2_robot/meshes/steer.STL" />
      </geometry>
      <material
        name="">
        <color
          rgba="1 1 1 1" />
      </material>
    </visual>
    <collision>
      <origin
        xyz="0 0 0"
        rpy="0 0 0" />
      <geometry>
        <mesh
          filename="package://my_ros2_robot/meshes/steer.STL" />
      </geometry>
    </collision>
  </link>
  <joint
    name="steer_joint"
    type="revolute">
    <origin
      xyz="0 0 0"
      rpy="0 0 0" />
    <parent
      link="base_link" />
    <child
      link="steer" />
    <axis
      xyz="0 1 0" />
    <limit
      lower="0"
      upper="0"
      effort="0"
      velocity="0" />
  </joint>
  <link
    name="wheel">
    <inertial>
      <origin
        xyz="0 -1.4572E-16 0"
        rpy="0 0 0" />
      <mass
        value="0.082467" />
      <inertia
        ixx="2.9379E-05"
        ixy="-1.4914E-21"
        ixz="2.1176E-22"
        iyy="4.733E-05"
        iyz="-1.6179E-18"
        izz="2.9379E-05" />
    </inertial>
    <visual>
      <origin
        xyz="0 0 0"
        rpy="0 0 0" />
      <geometry>
        <mesh
          filename="package://my_ros2_robot/meshes/wheel.STL" />
      </geometry>
      <material
        name="">
        <color
          rgba="0.79216 0.81961 0.93333 1" />
      </material>
    </visual>
    <collision>
      <origin
        xyz="0 0 0"
        rpy="0 0 0" />
      <geometry>
        <mesh
          filename="package://my_ros2_robot/meshes/wheel.STL" />
      </geometry>
    </collision>
  </link>
  <joint
    name="wheel_joint"
    type="continuous">
    <origin
      xyz="0 0 0"
      rpy="0 0 0" />
    <parent
      link="steer" />
    <child
      link="wheel" />
    <axis
      xyz="0 1 0" />
  </joint>
</robot>
